<?xml version="1.0" encoding="utf-8"?>
<!-- This URDF was automatically created by SolidWorks to URDF Exporter! Originally created by Stephen Brawner (brawner@gmail.com) 
     Commit Version: 1.6.0-4-g7f85cfe  Build Version: 1.6.7995.38578
     For more information, please see http://wiki.ros.org/sw_urdf_exporter -->
<robot
  name="mark_fbj">
  <link
    name="base_link">
    <inertial>
      <origin
        xyz="-0.033289 0.022731 0.125"
        rpy="0 0 0" />
      <mass
        value="0.85081" />
      <inertia
        ixx="0.0013939"
        ixy="7.9629E-06"
        ixz="8.9385E-13"
        iyy="0.0020002"
        iyz="9.055E-12"
        izz="0.0010651" />
    </inertial>
    <visual>
      <origin
        xyz="0 0 0"
        rpy="0 0 0" />
      <geometry>
        <mesh
          filename="package://mark_fbj/meshes/base_link.STL" />
      </geometry>
      <material
        name="">
        <color
          rgba="0.83529 0.10984 0.1451 1" />
      </material>
    </visual>
    <collision>
      <origin
        xyz="0 0 0"
        rpy="0 0 0" />
      <geometry>
        <mesh
          filename="package://mark_fbj/meshes/base_link.STL" />
      </geometry>
    </collision>
  </link>
  <link
    name="right_wheel">
    <inertial>
      <origin
        xyz="1.3878E-17 1.7347E-18 -0.01"
        rpy="0 0 0" />
      <mass
        value="0.099965" />
      <inertia
        ixx="4.3543E-05"
        ixy="-2.6386E-37"
        ixz="-4.4116E-24"
        iyy="4.3543E-05"
        iyz="-4.5918E-38"
        izz="8.0422E-05" />
    </inertial>
    <visual>
      <origin
        xyz="0 0 0"
        rpy="0 0 0" />
      <geometry>
        <mesh
          filename="package://mark_fbj/meshes/right_wheel.STL" />
      </geometry>
      <material
        name="">
        <color
          rgba="0.69019 0.68627 0.67843 1" />
      </material>
    </visual>
    <collision>
      <origin
        xyz="0 0 0"
        rpy="0 0 0" />
      <geometry>
        <mesh
          filename="package://mark_fbj/meshes/right_wheel.STL" />
      </geometry>
    </collision>
  </link>
  <joint
    name="right_wheel_joint"
    type="continuous">
    <origin
      xyz="-0.023709 -0.055 0.01262"
      rpy="1.5708 0 0" />
    <parent
      link="base_link" />
    <child
      link="right_wheel" />
    <axis
      xyz="0 0 1" />
  </joint>
  <link
    name="left_wheel">
    <inertial>
      <origin
        xyz="-3.4694E-18 1.7347E-18 0.01"
        rpy="0 0 0" />
      <mass
        value="0.099965" />
      <inertia
        ixx="4.3543E-05"
        ixy="-2.6386E-37"
        ixz="5.6028E-22"
        iyy="4.3543E-05"
        iyz="-9.0544E-38"
        izz="8.0422E-05" />
    </inertial>
    <visual>
      <origin
        xyz="0 0 0"
        rpy="0 0 0" />
      <geometry>
        <mesh
          filename="package://mark_fbj/meshes/left_wheel.STL" />
      </geometry>
      <material
        name="">
        <color
          rgba="0.69019 0.68627 0.67843 1" />
      </material>
    </visual>
    <collision>
      <origin
        xyz="0 0 0"
        rpy="0 0 0" />
      <geometry>
        <mesh
          filename="package://mark_fbj/meshes/left_wheel.STL" />
      </geometry>
    </collision>
  </link>
  <joint
    name="left_wheel_joint"
    type="continuous">
    <origin
      xyz="-0.023709 -0.195 0.01262"
      rpy="1.5708 0 0" />
    <parent
      link="base_link" />
    <child
      link="left_wheel" />
    <axis
      xyz="0 0 1" />
  </joint>
  <link
    name="camera_link">
    <inertial>
      <origin
        xyz="0.088101 0.0722 -0.011978"
        rpy="0 0 0" />
      <mass
        value="0.011651" />
      <inertia
        ixx="4.2448E-07"
        ixy="-3.6936E-23"
        ixz="4.3943E-22"
        iyy="2.8411E-06"
        iyz="3.3945E-10"
        izz="2.8535E-06" />
    </inertial>
    <visual>
      <origin
        xyz="0 0 0"
        rpy="0 0 0" />
      <geometry>
        <mesh
          filename="package://mark_fbj/meshes/camera_link.STL" />
      </geometry>
      <material
        name="">
        <color
          rgba="0.9803 0.9803 0.9725 1" />
      </material>
    </visual>
    <collision>
      <origin
        xyz="0 0 0"
        rpy="0 0 0" />
      <geometry>
        <mesh
          filename="package://mark_fbj/meshes/camera_link.STL" />
      </geometry>
    </collision>
  </link>
  <joint
    name="camera_link_joint"
    type="fixed">
    <origin
      xyz="-0.023709 -0.035 0.01262"
      rpy="-3.1279 0 -1.5708" />
    <parent
      link="base_link" />
    <child
      link="camera_link" />
    <axis
      xyz="1 0 0" />
    <limit
      lower="0"
      upper="0"
      effort="0"
      velocity="0" />
  </joint>
  <link
    name="sensor_link">
    <inertial>
      <origin
        xyz="0.0047846 -0.043843 0.017736"
        rpy="0 0 0" />
      <mass
        value="0.077493" />
      <inertia
        ixx="4.1051E-05"
        ixy="2.9646E-21"
        ixz="4.3944E-21"
        iyy="4.1051E-05"
        iyz="1.7231E-19"
        izz="6.5429E-05" />
    </inertial>
    <visual>
      <origin
        xyz="0 0 0"
        rpy="0 0 0" />
      <geometry>
        <mesh
          filename="package://mark_fbj/meshes/sensor_link.STL" />
      </geometry>
      <material
        name="">
        <color
          rgba="1 0.898 0.55294 1" />
      </material>
    </visual>
    <collision>
      <origin
        xyz="0 0 0"
        rpy="0 0 0" />
      <geometry>
        <mesh
          filename="package://mark_fbj/meshes/sensor_link.STL" />
      </geometry>
    </collision>
  </link>
  <joint
    name="sensor_link_joint"
    type="fixed">
    <origin
      xyz="-0.033162 -0.078327 0.052753"
      rpy="-0.0014827 0.013586 -0.10871" />
    <parent
      link="base_link" />
    <child
      link="sensor_link" />
    <axis
      xyz="0.10849 -0.9941 0" />
    <limit
      lower="0"
      upper="0"
      effort="0"
      velocity="0" />
  </joint>
</robot>